<?xml version="1.0" ?>
<robot xmlns:xacro="http://www.ros.org/wiki/xacro">

<xacro:include filename="$(find mecanum)/urdf/encoder_roller.xacro"/>

<xacro:macro
	name="encoder_macro"
	params="name color xyz rpy">

		<link name="encoder_${name}_link">
			<inertial>
				<origin xyz="0 0 -0.000343"/>
				<mass value="0.0835758"/>
				<inertia
					ixx="0.000165921"
					ixy="0"
					ixz="0"
					iyy="0.000165921"
					iyz="0"
					izz="0.00023508325"/>
			</inertial>
			<visual>
				<geometry>

					<mesh filename="package://mecanum/meshes/encoder.stl"/>
				</geometry>
				<material name="encoder_${name}_material">
					<color rgba="${color} 1"/>
				</material>
			</visual>
			<collision>
				<geometry>
					<mesh filename="package://mecanum/meshes/encoder.stl"/>
				</geometry>
			</collision>
			
		</link>
		<link name="slider_${name}_link">
			<inertial>
				<origin xyz="0 0.0 0.0" rpy="0.0 1.57 0.0"/>
				<mass value="0.01"/>
				<inertia ixx="0.0001" ixy="0.0" ixz="0.0" iyy="0.0001" iyz="0.0" izz="0.0001"/>
			</inertial>
			<visual>
				<origin xyz="0 0.0 0.0" rpy="0.0 1.57 0.0"/>
				<geometry>
					<box size="0.005 0.02 0.02"/>
				</geometry>
			</visual>
		</link>

		<joint name="slider_${name}_joint" type="prismatic">
			<parent link="base_link"/>
			<child link="slider_${name}_link"/>
			<axis xyz="0 1 0"/>
			<limit lower="0.0" upper="0.02" velocity="0.1" effort="200.0"/>
			<origin xyz="${xyz}" rpy="${rpy}"/>
		</joint>

		<joint
			name="encoder_${name}_joint"
			type="continuous">
			<parent link="slider_${name}_link" />
			<child link="encoder_${name}_link" />
			<axis xyz="0 0 1"/>
			<origin xyz="0 0 0" rpy="0 0 0"/>
			<limit effort="0" velocity="1" />
		</joint>
		
		<gazebo reference="slider_${name}_link">
  			<material>Gazebo/Orange</material>
  		</gazebo>


		<xacro:roller_macro
			parent="${name}"
			name="e"
			xyz="0.01355 0 0.0055"
			rpy="-1.570796326794896 0 0"
		/>
		<xacro:roller_macro
			parent="${name}"
			name="ne"
			xyz="0.00958129689 0.00958129689 -0.0055"
			rpy="-1.570796326794896 0 0.7853981633974483"
		/>
		<xacro:roller_macro
			parent="${name}"
			name="n"
			xyz="0 0.01355 0.0055"
			rpy="-1.570796326794896 0 1.570796326794896"
		/>
		<xacro:roller_macro
			parent="${name}"
			name="nw"
			xyz="-0.00958129689 0.00958129689 -0.0055"
			rpy="-1.570796326794896 0 2.356194490192345"
		/>
		<xacro:roller_macro
			parent="${name}"
			name="w"
			xyz="-0.01355 0 0.0055"
			rpy="-1.570796326794896 0 3.141592653589793"
		/>
		<xacro:roller_macro
			parent="${name}"
			name="sw"
			xyz="-0.00958129689 -0.00958129689 -0.0055"
			rpy="-1.570796326794896 0 -2.356194490192345"
		/>
		<xacro:roller_macro
			parent="${name}"
			name="s"
			xyz="0 -0.01355 0.0055"
			rpy="-1.570796326794896 0 -1.570796326794896"
		/>
		<xacro:roller_macro
			parent="${name}"
			name="se"
			xyz="0.00958129689 -0.00958129689 -0.0055"
			rpy="-1.570796326794896 0 -0.7853981633974483"
		/>
	<transmission name="slider_${name}_transmission">
  	  <type>transmission_interface/SimpleTransmission</type>
  	  <joint name="slider_${name}_joint">
  	    <hardwareInterface>hardware_interface/EffortJointInterface</hardwareInterface>
  	  </joint>
  	  <actuator name="slider_${name}_motor">
  	    <hardwareInterface>hardware_interface/EffortJointInterface</hardwareInterface>
  	    <mechanicalReduction>1</mechanicalReduction>
  	  </actuator>
  	</transmission>
	<transmission name="encoder_${name}_transmission">
		<type>transmission_interface/SimpleTransmission</type>
		<joint name="encoder_${name}_joint">
			<hardwareInterface>hardware_interface/VelocityJointInterface</hardwareInterface>
		</joint>
		<actuator name="encoder_${name}_motor">
			<hardwareInterface>hardware_interface/VelocityJointInterface</hardwareInterface>
			<mechanicalReduction>1</mechanicalReduction>
		</actuator>
	</transmission>

	</xacro:macro>

</robot>
